Workbook

Sheet Menu
C3: MENÚ GENERAL
C6: PRIMER CONTEO | F6: CONTEO A1
C8: G3 | F8: CONTEO A2
F10: CONTEO A3
F12: CONTEO A4
C14: INFORME FINAL | F14: CONTEO SOBRES

Sheet Primer Conteo
B2: Primer Conteo | E2: VOLVER AL MENÚ
B3: Area: | C3: A1
B4: Adultos :
B5: Niños :
B8: Area: | C8: A2
B9: Adultos :
B10: Niños :
B13: Area:6 | C13: A3
B14: Adultos :
B15: Niños :
B18: Area: | C18: A4
B19: Adultos :
B20: Niños :
B24: Servicio | C24: =UPPER(TEXT(B25,"dddd")) -> MIÉRCOLES
B25: =TODAY() -> 46064 | C25: ='Inf. Final'!C7 -> 08:00 AM
B26: Primer Conteo
B27: Total Adultos:
B28: Total Niños:
B29: Total Asistencia:
B33: Total Final Asistencia
B34: Total Adultos:
B35: Total Niños:
B36: Total Asistencia:
B39: =B24 -> Servicio | C39: =C24 -> MIÉRCOLES
B40: =TODAY() -> 46064 | C40: =C25 -> 08:00 AM
B41: Segundo Conteo
B42: Total Adultos:
B43: Total Niños:
B44: Total Asistencia:

Sheet A1
C2: GRUPO 3
C3: AREA : A1 FECHA: | D3: =TODAY() -> 46064
C6: Total sillas del área.
C7: Total silla vacías
C8: Total personas
C9: Total niños A1
C12: Servidores
C13: Comunicaciones (dentro del auditorio)
C14: Logística
C15: Alabanza
C18: Servidora de Pastora:
B22: VOLVER AL MENÚ

Sheet A2
C2: GRUPO 3
C3: AREA : A2 FECHA:
C6: Total sillas del área.
C7: Total silla vacías
C8: Total person
C9: Total niños A2
C12: Servidores
C13: Logística
C14: Jesus Place
C15: Datáfono
C16: Ministerial
B19: VOLVER AL MENÚ
I23: 2

Sheet A3
C2: GRUPO 3
C3: AREA : A3 FECHA:
C6: Total sillas del área.
C7: Total sila vacías
C8: Total personas
C9: Total niños A3
C12: Servidores
C13: Logística
C14: Consolidación
B17: VOLVER AL MENÚ

Sheet A4
C2: GRUPO 3
C3: AREA : A4 FECHA:
B6: EXTERIORES
C8: Servidores
C9: Logística
C10: Coffe.
C11: Container
C18: Vehículos
C19: Motos
C20: Bicicletas
C21: TOTAL VEHICULOS
B24: IGLEKIDS
C26: Coordinadoras:
C27: Supervisoras:
C28: Maestros:
B30: Personal de Apoyo | C30: Recrearte:
C31: Regikids:
C32: Logikids:
C33: Salud Kids:
C34: Yo Soy
C35: Total Apoyo:
C37: Total área Iglekids:
C38: Niños:
B42: VOLVER AL MENÚ

Sheet Sobres
B3: Inventario de Sobres
B6: Clase | C6: Inv.nicial | D6: Ingresados | E6: Tot.Inicial | F6: Entregados | G6: Inv.Final
B7: Ofrenda
B8: Protemplo
B9: Iglekids
B12: Canastas:
B16: VOLVER AL MENÚ

Sheet Servicios
A1: N° Serv. | B1: Hora
A2: 0 | B2: 07:00 PM
A3: 1 | B3: 08:00 AM
A4: 2 | B4: 09:00 AM
A5: 3 | B5: 11:00 AM
A6: 4 | B6: 05:30 PM
A7: 5 | B7: 06:00 PM

Sheet Consolidado
B2: FECHA | C2: =TODAY() -> 46064
B5: AUDITORIO
B6: RESUMEN GENERAL | C6: A1 | D6: A2 | E6: A3 | F6: A4 | G6: TOTALES
B7: Sillas del área. | C7: ='A1'!D6 -> 0 | D7: ='A2'!D6 -> 0 | E7: ='A3'!D6 -> 0 | G7: =SUM(C7:E7) -> 0
B8: Silla vacías | C8: ='A1'!D7 -> 0 | D8: ='A2'!D7 -> 0 | E8: ='A3'!D7 -> 0 | G8: =SUM(C8:E8) -> 0
B9: Total Personas | C9: ='A1'!D8 -> 0 | D9: ='A2'!D8 -> 0 | E9: ='A3'!D8 -> 0 | G9: =SUM(C9:E9) -> 0
B10: Total niños | C10: ='A1'!D9 -> 0 | D10: ='A2'!D9 -> 0 | E10: ='A3'!D9 -> 0 | G10: =SUM(C10:E10) -> 0
B11: Total AUDITORIO | C11: =SUM(C7:C10) -> 0 | D11: =SUM(D7:D10) -> 0 | E11: =SUM(E7:E10) -> 0
B13: SERVIDORES
B14: Areas | C14: A1 | D14: A2 | E14: A3 | F14: A4 | G14: TOTAL
B15: Servidores: | C15: ='A1'!D12 -> 0 | D15: ='A2'!D12 -> 0 | E15: ='A3'!D12 -> 0 | F15: ='A4'!D8 -> 0 | G15: =SUM(C15:F15) -> 0
B16: Consolidación: | E16: ='A3'!D14 -> 0 | G16: =SUM(C16:F16) -> 0
B17: Comunicaciones: | C17: ='A1'!D13 -> 0 | G17: =SUM(C17:F17) -> 0
B18: Logistica: | C18: ='A1'!D14 -> 0 | D18: ='A2'!D13 -> 0 | E18: ='A3'!D13 -> 0 | F18: ='A4'!D9 -> 0 | G18: =SUM(C18:F18) -> 0
B19: Jesus place: | D19: ='A2'!D14 -> 0 | G19: =SUM(C19:F19) -> 0
B20: Datafono: | D20: ='A2'!D15 -> 0 | G20: =SUM(C20:F20) -> 0
B21: Coffee: | F21: ='A4'!D10 -> 0 | G21: =SUM(C21:F21) -> 0
B22: Ministerial: | D22: ='A2'!D16 -> 0 | G22: =SUM(C22:F22) -> 0
B23: Alabanza: | C23: ='A1'!D15 -> 0 | G23: =SUM(C23:F23) -> 0
B24: VIP: | C24: ='A1'!D18 -> 0 | G24: =SUM(C24:F24) -> 0
B25: Iglekids: | F25: ='A4'!D37 -> 0 | G25: =SUM(C25:F25) -> 0
B26: Total Servidores | C26: =SUM(C15:C25) -> 0 | D26: =SUM(D15:D25) -> 0 | E26: =SUM(E15:E25) -> 0 | F26: =SUM(F15:F25) -> 0 | G26: =SUM(G15:G25) -> 0
B28: PARQUEADERO
B29: VEHICULOS
B30: Carros | F30: ='A4'!D18 -> 0
B31: Motos | F31: ='A4'!D19 -> 0
B32: Bicicletas | F32: ='A4'!D20 -> 0
B33: Total Vehiculos | F33: =SUM(F30:F32) -> 0

Sheet Inf. Final
B2: *Informe de Servicio Grupo 3*
B4: =TODAY() -> 46064
B5: N° Servicio: | C5: 1
B6: Sede | C6: =(IF(C5=4, "Bocagrande", "Villa Grande")) -> Villa Grande
B7: =UPPER(TEXT(B4,"dddd")) -> MIÉRCOLES | C7: =VLOOKUP(C5,Servicios!A1:B7,2,FALSE()) -> 08:00 AM
B9: 1️⃣ Asistencia Personas
B11: ➕*Asistencia Personas *
B13: ➖En Sillas: | C13: =SUM(Consolidado!C9:D9) -> 0
B14: ➖En Gradas: | C14: =Consolidado!E9 -> 0
B15: ➖Niños Auditorio: | C15: =Consolidado!G10 -> 0
B16: ➖Niños Iglekids | C16: ='A4'!D38 -> 0
B18: 🟰* Total Auditorio *: | C18: =SUM(C13:C16) -> 0
B20: ➕Area De Servidores:
B22: ➖Servidores: | C22: =Consolidado!G15 -> 0
B23: ➖Consolidación: | C23: =Consolidado!G16 -> 0
B24: ➖Comunicaciones: | C24: =Consolidado!G17 -> 0
B25: ➖Logistica: | C25: =Consolidado!G18 -> 0
B26: ➖Jesus place: | C26: =Consolidado!G19 -> 0
B27: ➖Datafono: | C27: =Consolidado!G20 -> 0
B28: ➖Coffee: | C28: =Consolidado!G21 -> 0
B29: ➖Ministerial: | C29: =Consolidado!G22 -> 0
B30: ➖Alabanza: | C30: =Consolidado!G23 -> 0
B31: ➖VIP: | C31: =Consolidado!G24 -> 0
B32: ➖Iglekids: | C32: =Consolidado!G25 -> 0
B35: 🟰Total Área Servidores: | C35: =SUM(C22:C32) -> 0
B37: 🟰Total Personas Iglesia: | C37: =C18+C35 -> 0
B39: 2️⃣ Vehículos:
B41: ➖Carros: | C41: =Consolidado!F30 -> 0
B42: ➖Motos: | C42: =Consolidado!F31 -> 0
B43: ➖Bicicletas: | C43: =Consolidado!F32 -> 0
B45: 🟰🟰 Total Vehículos: | C45: =SUM(C41:C43) -> 0
B47: 3️⃣ Ofrendas
B49: ➕Canastas Ofrendas:
B51: ➖ Entregadas: | C51: =Sobres!C12 -> 0
B53: ➕Sobres Ofrendas
B55: ➖Inicial Ofrendas: | C55: =Sobres!C7 -> 0
B56: ➖Recibidos: | C56: =Sobres!D7 -> 0
B57: 🟰Total: | C57: =Sobres!E7 -> 0
B58: ➖Entregados: | C58: =Sobres!F7 -> 0
B59: 🟰🟰Final Ofrendas: | C59: =Sobres!G7 -> 0
...
